08/26/2021 13:08:09 - INFO - STDOUT: [31mProcess Process-1:
08/26/2021 13:08:09 - ERROR - STDERR: Process Process-1:
08/26/2021 13:08:09 - INFO - STDOUT: [0m[31mTraceback (most recent call last):
08/26/2021 13:08:09 - ERROR - STDERR: Traceback (most recent call last):
08/26/2021 13:08:09 - INFO - STDOUT: [0m[31m[0m[31m  File "/home/castel/anaconda3/envs/torch/lib/python3.8/multiprocessing/process.py", line 315, in _bootstrap
08/26/2021 13:08:09 - INFO - STDOUT:     self.run()
08/26/2021 13:08:09 - ERROR - STDERR:   File "/home/castel/anaconda3/envs/torch/lib/python3.8/multiprocessing/process.py", line 315, in _bootstrap
08/26/2021 13:08:09 - ERROR - STDERR:     self.run()
08/26/2021 13:08:09 - INFO - STDOUT: [0m[31m[0m[31m  File "/home/castel/anaconda3/envs/torch/lib/python3.8/multiprocessing/process.py", line 108, in run
08/26/2021 13:08:09 - INFO - STDOUT:     self._target(*self._args, **self._kwargs)
08/26/2021 13:08:09 - ERROR - STDERR:   File "/home/castel/anaconda3/envs/torch/lib/python3.8/multiprocessing/process.py", line 108, in run
08/26/2021 13:08:09 - ERROR - STDERR:     self._target(*self._args, **self._kwargs)
08/26/2021 13:08:09 - INFO - STDOUT: [0m[31m[0m[31m  File "/home/castel/gitclone/TSDD/src/main_experiments.py", line 48, in run
08/26/2021 13:08:09 - INFO - STDOUT:     df_run = single_experiment(args, path)
08/26/2021 13:08:09 - ERROR - STDERR:   File "/home/castel/gitclone/TSDD/src/main_experiments.py", line 48, in run
08/26/2021 13:08:09 - ERROR - STDERR:     df_run = single_experiment(args, path)
08/26/2021 13:08:09 - INFO - STDOUT: [0m[31m[0m[31m  File "/home/castel/gitclone/TSDD/src/main_experiments.py", line 318, in single_experiment
08/26/2021 13:08:09 - INFO - STDOUT:     x_train, Y_train, x_valid, Y_valid, x_test, Y_test, t_start, t_end = load_corrupt_data(args)
08/26/2021 13:08:09 - ERROR - STDERR:   File "/home/castel/gitclone/TSDD/src/main_experiments.py", line 318, in single_experiment
08/26/2021 13:08:09 - ERROR - STDERR:     x_train, Y_train, x_valid, Y_valid, x_test, Y_test, t_start, t_end = load_corrupt_data(args)
08/26/2021 13:08:09 - INFO - STDOUT: [0m[31m[0m[31m  File "/home/castel/gitclone/TSDD/src/main_experiments.py", line 242, in load_corrupt_data
08/26/2021 13:08:09 - INFO - STDOUT:     X, y = load_data(args.dataset)
08/26/2021 13:08:09 - ERROR - STDERR:   File "/home/castel/gitclone/TSDD/src/main_experiments.py", line 242, in load_corrupt_data
08/26/2021 13:08:09 - ERROR - STDERR:     X, y = load_data(args.dataset)
08/26/2021 13:08:09 - INFO - STDOUT: [0m[31m[0m[31m  File "/home/castel/gitclone/TSDD/src/utils/load_datasets.py", line 31, in load_data
08/26/2021 13:08:09 - INFO - STDOUT:     assert dataset in available_datasets.keys(), f'{dataset=} not available. ' \
08/26/2021 13:08:09 - ERROR - STDERR:   File "/home/castel/gitclone/TSDD/src/utils/load_datasets.py", line 31, in load_data
08/26/2021 13:08:09 - ERROR - STDERR:     assert dataset in available_datasets.keys(), f'{dataset=} not available. ' \
08/26/2021 13:08:09 - INFO - STDOUT: [0m[31m[0m[31mAssertionError: dataset='fin_wine' not available. Existing datasets are []
08/26/2021 13:08:09 - ERROR - STDERR: AssertionError: dataset='fin_wine' not available. Existing datasets are []
08/26/2021 13:08:09 - INFO - STDOUT: [0m[31m[0m
